{"uuid": "c4926fd5-af9d-4cb8-8ec1-abe15f9c3309", "children": ["89d9ba96-ee50-4cd7-b623-d4414b5d4ce5"], "befores": [{"name": "get_driver", "status": "passed", "start": 1577192603635, "stop": 1577192621699}], "afters": [{"name": "get_driver::0", "status": "broken", "statusDetails": {"message": "selenium.common.exceptions.InvalidSessionIdException: Message: Tried to run command without establishing a connection\n\n", "trace": "  File \"C:\\Users\\tolos\\AppData\\Local\\Packages\\PythonSoftwareFoundation.Python.3.7_qbz5n2kfra8p0\\LocalCache\\local-packages\\Python37\\site-packages\\allure_commons\\_allure.py\", line 185, in __call__\n    return self._fixture_function(*args, **kwargs)\n  File \"C:\\Users\\tolos\\AppData\\Local\\Packages\\PythonSoftwareFoundation.Python.3.7_qbz5n2kfra8p0\\LocalCache\\local-packages\\Python37\\site-packages\\_pytest\\fixtures.py\", line 795, in _teardown_yield_fixture\n    next(it)\n  File \"C:\\Users\\tolos\\Documents\\GitHub\\CH_096_TAQC\\Tests\\conftest.py\", line 20, in get_driver\n    driver.close()\n  File \"C:\\Users\\tolos\\AppData\\Local\\Packages\\PythonSoftwareFoundation.Python.3.7_qbz5n2kfra8p0\\LocalCache\\local-packages\\Python37\\site-packages\\selenium\\webdriver\\remote\\webdriver.py\", line 688, in close\n    self.execute(Command.CLOSE)\n  File \"C:\\Users\\tolos\\AppData\\Local\\Packages\\PythonSoftwareFoundation.Python.3.7_qbz5n2kfra8p0\\LocalCache\\local-packages\\Python37\\site-packages\\selenium\\webdriver\\remote\\webdriver.py\", line 321, in execute\n    self.error_handler.check_response(response)\n  File \"C:\\Users\\tolos\\AppData\\Local\\Packages\\PythonSoftwareFoundation.Python.3.7_qbz5n2kfra8p0\\LocalCache\\local-packages\\Python37\\site-packages\\selenium\\webdriver\\remote\\errorhandler.py\", line 242, in check_response\n    raise exception_class(message, screen, stacktrace)\n"}, "start": 1577192635968, "stop": 1577192635970}], "start": 1577192603635, "stop": 1577192635970}