{"uuid": "ba3c1dc2-d44c-4f17-bdcf-f81914811abd", "children": ["af32e6ec-21af-4a22-907a-182f473f7520"], "befores": [{"name": "get_driver", "status": "broken", "statusDetails": {"message": "selenium.common.exceptions.WebDriverException: Message: Reached error page: about:neterror?e=connectionFailure&u=https%3A//localhost%3A44364/home/events%3Fpage%3D1&c=UTF-8&f=regular&d=Firefox%20%D0%BD%D0%B5%20%D0%BC%D0%BE%D0%B6%D0%B5%20%D0%B2%D1%81%D1%82%D0%B0%D0%BD%D0%BE%D0%B2%D0%B8%D1%82%D0%B8%20%D0%B7%E2%80%99%D1%94%D0%B4%D0%BD%D0%B0%D0%BD%D0%BD%D1%8F%20%D0%B7%20%D1%81%D0%B5%D1%80%D0%B2%D0%B5%D1%80%D0%BE%D0%BC%20localhost%3A44364.\n\n", "trace": "  File \"C:\\Users\\tolos\\AppData\\Local\\Packages\\PythonSoftwareFoundation.Python.3.7_qbz5n2kfra8p0\\LocalCache\\local-packages\\Python37\\site-packages\\pluggy\\callers.py\", line 187, in _multicall\n    res = hook_impl.function(*args)\n  File \"C:\\Users\\tolos\\AppData\\Local\\Packages\\PythonSoftwareFoundation.Python.3.7_qbz5n2kfra8p0\\LocalCache\\local-packages\\Python37\\site-packages\\_pytest\\fixtures.py\", line 957, in pytest_fixture_setup\n    result = call_fixture_func(fixturefunc, request, kwargs)\n  File \"C:\\Users\\tolos\\AppData\\Local\\Packages\\PythonSoftwareFoundation.Python.3.7_qbz5n2kfra8p0\\LocalCache\\local-packages\\Python37\\site-packages\\_pytest\\fixtures.py\", line 783, in call_fixture_func\n    res = next(it)\n  File \"C:\\Users\\tolos\\Documents\\GitHub\\CH_096_TAQC\\Tests\\conftest.py\", line 17, in get_driver\n    driver.get(Config.HOME_URL)\n  File \"C:\\Users\\tolos\\AppData\\Local\\Packages\\PythonSoftwareFoundation.Python.3.7_qbz5n2kfra8p0\\LocalCache\\local-packages\\Python37\\site-packages\\selenium\\webdriver\\remote\\webdriver.py\", line 333, in get\n    self.execute(Command.GET, {'url': url})\n  File \"C:\\Users\\tolos\\AppData\\Local\\Packages\\PythonSoftwareFoundation.Python.3.7_qbz5n2kfra8p0\\LocalCache\\local-packages\\Python37\\site-packages\\selenium\\webdriver\\remote\\webdriver.py\", line 321, in execute\n    self.error_handler.check_response(response)\n  File \"C:\\Users\\tolos\\AppData\\Local\\Packages\\PythonSoftwareFoundation.Python.3.7_qbz5n2kfra8p0\\LocalCache\\local-packages\\Python37\\site-packages\\selenium\\webdriver\\remote\\errorhandler.py\", line 242, in check_response\n    raise exception_class(message, screen, stacktrace)\n"}, "start": 1577192116843, "stop": 1577192132175}], "start": 1577192116843, "stop": 1577192132516}