{"uuid": "c0c03326-ae2e-4511-b2a6-ef2b8b9794eb", "children": ["97d18150-2ada-4741-8ed7-ddf3308b59f9"], "befores": [{"name": "driver_init", "status": "broken", "statusDetails": {"message": "selenium.common.exceptions.WebDriverException: Message: Reached error page: about:neterror?e=connectionFailure&u=http%3A//localhost%3A49862/home/events%3Fpage%3D1&c=UTF-8&f=regular&d=Firefox%20%D0%BD%D0%B5%20%D0%BC%D0%BE%D0%B6%D0%B5%D1%82%20%D1%83%D1%81%D1%82%D0%B0%D0%BD%D0%BE%D0%B2%D0%B8%D1%82%D1%8C%20%D1%81%D0%BE%D0%B5%D0%B4%D0%B8%D0%BD%D0%B5%D0%BD%D0%B8%D0%B5%20%D1%81%20%D1%81%D0%B5%D1%80%D0%B2%D0%B5%D1%80%D0%BE%D0%BC%20localhost%3A49862.\n\n", "trace": "  File \"d:\\documents\\github\\.ev_env\\lib\\site-packages\\pluggy\\callers.py\", line 187, in _multicall\n    res = hook_impl.function(*args)\n  File \"d:\\documents\\github\\.ev_env\\lib\\site-packages\\_pytest\\fixtures.py\", line 957, in pytest_fixture_setup\n    result = call_fixture_func(fixturefunc, request, kwargs)\n  File \"d:\\documents\\github\\.ev_env\\lib\\site-packages\\_pytest\\fixtures.py\", line 787, in call_fixture_func\n    res = fixturefunc(**kwargs)\n  File \"d:\\Documents\\GitHub\\.Ev_env\\CH_096_TAQC\\Tests\\conftest.py\", line 16, in driver_init\n    driver.get(Config.HOME_URL)\n  File \"d:\\documents\\github\\.ev_env\\lib\\site-packages\\selenium\\webdriver\\remote\\webdriver.py\", line 333, in get\n    self.execute(Command.GET, {'url': url})\n  File \"d:\\documents\\github\\.ev_env\\lib\\site-packages\\selenium\\webdriver\\remote\\webdriver.py\", line 321, in execute\n    self.error_handler.check_response(response)\n  File \"d:\\documents\\github\\.ev_env\\lib\\site-packages\\selenium\\webdriver\\remote\\errorhandler.py\", line 242, in check_response\n    raise exception_class(message, screen, stacktrace)\n"}, "start": 1577127671149, "stop": 1577127686915}], "start": 1577127671149, "stop": 1577127687118}